Workbook

Sheet Work_Orders
A1: Job_ID | B1: Date_Logged | C1: Category | D1: Description | E1: Priority | F1: Status | G1: Contractor | H1: Days_to_Close | I1: Cost_EUR | J1: Building
A2: WO-1001 | B2: 2024-01-05 | C2: Electrical | D2: Faulty lighting in corridor | E2: Low | F2: Completed | G2: ProClean | H2: 4 | I2: 1717.61 | J2: Student Centre
A3: WO-1002 | B3: 2024-01-17 | C3: Electrical | D3: Power socket not working | E3: High | F3: Completed | G3: TechFix Dublin | H3: 20 | I3: 144.22 | J3: Admin Block
A4: WO-1003 | B4: 2024-01-26 | C4: Structural | D4: Door hinge repair | E4: High | F4: Completed | G4: TechFix Dublin | H4: 1 | I4: 1916.31 | J4: Student Centre
A5: WO-1004 | B5: 2024-01-25 | C5: IT Equipment | D5: Monitor replacement | E5: Medium | F5: Completed | G5: Murphy Maintenance | H5: 11 | I5: 327.35 | J5: Library
A6: WO-1005 | B6: 2024-01-24 | C6: IT Equipment | D6: Monitor replacement | E6: Medium | F6: In Progress | G6: ProClean | J6: Main Campus
A7: WO-1006 | B7: 2024-01-21 | C7: Structural | D7: Window seal replacement | E7: High | F7: Completed | G7: ProClean | H7: 20 | I7: 2222.79 | J7: Research Block
A8: WO-1007 | B8: 2024-01-10 | C8: Plumbing | D8: Leaking tap in kitchen | E8: High | F8: Completed | G8: Lift Tech Ireland | H8: 3 | I8: 2149.87 | J8: Library
A9: WO-1008 | B9: 2024-01-12 | C9: Fire Safety | D9: Emergency exit sign repair | E9: Medium | F9: Completed | G9: TechFix Dublin | H9: 12 | I9: 587.01 | J9: Main Campus
A10: WO-1009 | B10: 2024-02-21 | C10: Lift | D10: Emergency stop test | E10: High | F10: Completed | G10: BuildRight Ltd | H10: 18 | I10: 611.47 | J10: Main Campus
A11: WO-1010 | B11: 2024-02-13 | C11: Lift | D11: Emergency stop test | E11: Low | F11: In Progress | G11: Murphy Maintenance | J11: Research Block
A12: WO-1011 | B12: 2024-02-21 | C12: IT Equipment | D12: Network switch fault | E12: High | F12: Completed | G12: ElecFix Ltd | H12: 15 | I12: 425.75 | J12: Admin Block
A13: WO-1012 | B13: 2024-02-19 | C13: Cleaning | D13: Carpet cleaning | E13: Low | F13: Completed | G13: ProClean | H13: 13 | I13: 956.03 | J13: Student Centre
A14: WO-1013 | B14: 2024-02-05 | C14: Plumbing | D14: Blocked drain | E14: Low | F14: In Progress | G14: BuildRight Ltd | J14: Student Centre
A15: WO-1014 | B15: 2024-02-15 | C15: Plumbing | D15: Leaking tap in kitchen | E15: Medium | F15: Completed | G15: TechFix Dublin | H15: 17 | I15: 688.42 | J15: Main Campus
A16: WO-1015 | B16: 2024-02-10 | C16: Cleaning | D16: Deep clean after event | E16: Low | F16: Completed | G16: TechFix Dublin | H16: 14 | I16: 462.74 | J16: Library
A17: WO-1016 | B17: 2024-02-21 | C17: HVAC | D17: Ventilation filter replacement | E17: Medium | F17: Completed | G17: ElecFix Ltd | H17: 10 | I17: 2116.84 | J17: Library
A18: WO-1017 | B18: 2024-02-17 | C18: HVAC | D18: AC unit not cooling | E18: Medium | F18: In Progress | G18: ProClean | J18: Library
A19: WO-1018 | B19: 2024-03-27 | C19: Electrical | D19: Power socket not working | E19: High | F19: Completed | G19: ProClean | H19: 10 | I19: 659.47 | J19: Main Campus
A20: WO-1019 | B20: 2024-03-25 | C20: Plumbing | D20: Blocked drain | E20: Low | F20: In Progress | G20: ElecFix Ltd | J20: Student Centre
A21: WO-1020 | B21: 2024-03-14 | C21: HVAC | D21: Ventilation filter replacement | E21: Medium | F21: In Progress | G21: ProClean | J21: Research Block
A22: WO-1021 | B22: 2024-03-12 | C22: Cleaning | D22: Pressure wash carpark | E22: Medium | F22: Completed | G22: Murphy Maintenance | H22: 15 | I22: 2257.07 | J22: Research Block
A23: WO-1022 | B23: 2024-03-18 | C23: Lift | D23: Lift door sensor fault | E23: High | F23: Completed | G23: Murphy Maintenance | H23: 8 | I23: 1504.03 | J23: Main Campus
A24: WO-1023 | B24: 2024-03-11 | C24: Lift | D24: Emergency stop test | E24: High | F24: Completed | G24: TechFix Dublin | H24: 3 | I24: 1324.26 | J24: Student Centre
A25: WO-1024 | B25: 2024-03-19 | C25: Lift | D25: Lift button replacement | E25: Medium | F25: In Progress | G25: ElecFix Ltd | J25: Student Centre
A26: WO-1025 | B26: 2024-03-14 | C26: Structural | D26: Flooring repair | E26: High | F26: Completed | G26: BuildRight Ltd | H26: 12 | I26: 1105.06 | J26: Main Campus
A27: WO-1026 | B27: 2024-03-26 | C27: Plumbing | D27: Leaking tap in kitchen | E27: High | F27: In Progress | G27: ElecFix Ltd | J27: Research Block
A28: WO-1027 | B28: 2024-03-06 | C28: Lift | D28: Lift door sensor fault | E28: Medium | F28: Completed | G28: Lift Tech Ireland | H28: 9 | I28: 1199.56 | J28: Admin Block
A29: WO-1028 | B29: 2024-03-27 | C29: Plumbing | D29: Leaking tap in kitchen | E29: High | F29: Pending | G29: Murphy Maintenance | J29: Research Block
A30: WO-1029 | B30: 2024-03-28 | C30: HVAC | D30: Ventilation filter replacement | E30: Medium | F30: Completed | G30: Lift Tech Ireland | H30: 13 | I30: 2263.91 | J30: Main Campus
A31: WO-1030 | B31: 2024-03-15 | C31: Structural | D31: Window seal replacement | E31: Medium | F31: In Progress | G31: Lift Tech Ireland | J31: Admin Block
A32: WO-1031 | B32: 2024-03-02 | C32: Fire Safety | D32: Fire extinguisher inspection | E32: High | F32: Completed | G32: TechFix Dublin | H32: 19 | I32: 1860.48 | J32: Library
A33: WO-1032 | B33: 2024-04-28 | C33: Electrical | D33: Faulty lighting in corridor | E33: Medium | F33: Completed | G33: BuildRight Ltd | H33: 17 | I33: 460.99 | J33: Research Block
A34: WO-1033 | B34: 2024-04-08 | C34: Plumbing | D34: Blocked drain | E34: Medium | F34: Completed | G34: ProClean | H34: 13 | I34: 370.13 | J34: Admin Block
A35: WO-1034 | B35: 2024-04-19 | C35: Electrical | D35: Emergency lighting test | E35: Medium | F35: Completed | G35: ElecFix Ltd | H35: 19 | I35: 1345.13 | J35: Library
A36: WO-1035 | B36: 2024-04-21 | C36: Lift | D36: Lift door sensor fault | E36: Medium | F36: Completed | G36: Murphy Maintenance | H36: 10 | I36: 1186.48 | J36: Student Centre
A37: WO-1036 | B37: 2024-04-09 | C37: Plumbing | D37: Leaking tap in kitchen | E37: High | F37: Completed | G37: ElecFix Ltd | H37: 5 | I37: 2338.49 | J37: Library
A38: WO-1037 | B38: 2024-04-23 | C38: Cleaning | D38: Window cleaning | E38: High | F38: In Progress | G38: ProClean | J38: Admin Block
A39: WO-1038 | B39: 2024-04-22 | C39: Electrical | D39: Power socket not working | E39: Low | F39: Completed | G39: CoolAir Services | H39: 4 | I39: 2352.21 | J39: Main Campus
A40: WO-1039 | B40: 2024-05-23 | C40: HVAC | D40: Heating system fault | E40: Medium | F40: Completed | G40: ProClean | H40: 11 | I40: 572.71 | J40: Student Centre
...

Sheet Summary_Analysis
A1: FACILITIES MAINTENANCE DASHBOARD — 2024 ANNUAL SUMMARY
A2: Royal College of Surgeons Ireland (RCSI) — Fictional Training Dataset
A4: Total Work Orders | B4: Completed | C4: In Progress | D4: Pending | E4: Avg Days to Close | F4: Total Cost (€)
A5: =COUNTA(Work_Orders!A2:A500)-COUNTBLANK(Work_Orders!A2:A500) -> -245 | B5: =COUNTIF(Work_Orders!F2:F500,"Completed") -> 87 | C5: =COUNTIF(Work_Orders!F2:F500,"In Progress") -> 25 | D5: =COUNTIF(Work_Orders!F2:F500,"Pending") -> 15 | E5: =AVERAGEIF(Work_Orders!F2:F500,"Completed",Work_Orders!H2:H500) -> 11.678161 | F5: =SUMIF(Work_Orders!F2:F500,"Completed",Work_Orders!I2:I500) -> 120798.28
A7: WORK ORDERS BY CATEGORY | E7: WORK ORDERS BY PRIORITY
A8: Category | B8: Count | C8: % of Total | E8: Priority | F8: Count | G8: Avg Cost (€)
A9: Electrical | B9: =COUNTIF(Work_Orders!C:C,A9) -> 13 | C9: =B9/B5 -> 0.14942529 | E9: High | F9: =COUNTIF(Work_Orders!E:E,E9) -> 29 | G9: =AVERAGEIFS(Work_Orders!I:I,Work_Orders!E:E,E9,Work_Orders!F:F,"Completed") -> 1400.973
A10: Plumbing | B10: =COUNTIF(Work_Orders!C:C,A10) -> 18 | C10: =B10/B5 -> 0.20689655 | E10: Medium | F10: =COUNTIF(Work_Orders!E:E,E10) -> 56 | G10: =AVERAGEIFS(Work_Orders!I:I,Work_Orders!E:E,E10,Work_Orders!F:F,"Completed") -> 1421.2726
A11: HVAC | B11: =COUNTIF(Work_Orders!C:C,A11) -> 14 | C11: =B11/B5 -> 0.16091954 | E11: Low | F11: =COUNTIF(Work_Orders!E:E,E11) -> 42 | G11: =AVERAGEIFS(Work_Orders!I:I,Work_Orders!E:E,E11,Work_Orders!F:F,"Completed") -> 1323.4148
A12: Lift | B12: =COUNTIF(Work_Orders!C:C,A12) -> 21 | C12: =B12/B5 -> 0.24137931
A13: Cleaning | B13: =COUNTIF(Work_Orders!C:C,A13) -> 18 | C13: =B13/B5 -> 0.20689655
A14: IT Equipment | B14: =COUNTIF(Work_Orders!C:C,A14) -> 13 | C14: =B14/B5 -> 0.14942529
A15: Structural | B15: =COUNTIF(Work_Orders!C:C,A15) -> 16 | C15: =B15/B5 -> 0.18390805
A16: Fire Safety | B16: =COUNTIF(Work_Orders!C:C,A16) -> 14 | C16: =B16/B5 -> 0.16091954
A17: TOTAL | B17: =SUM(B9:B16) -> 127 | C17: 100%
A19: MONTHLY WORK ORDER TREND — 2024
A20: Month | B20: Jobs Logged | C20: Completed | D20: Cost (€)
A21: Jan | B21: =COUNTIFS(Work_Orders!B:B,">=2024-01-01",Work_Orders!B:B,"<=2024-01-31") -> 0 | C21: =COUNTIFS(Work_Orders!B:B,">=2024-01-01",Work_Orders!B:B,"<=2024-01-31",Work_Orders!F:F,"Completed") -> 0 | D21: =SUMIFS(Work_Orders!I:I,Work_Orders!B:B,">=2024-01-01",Work_Orders!B:B,"<=2024-01-31") -> 0
A22: Feb | B22: =COUNTIFS(Work_Orders!B:B,">=2024-02-01",Work_Orders!B:B,"<=2024-02-31") -> 0 | C22: =COUNTIFS(Work_Orders!B:B,">=2024-02-01",Work_Orders!B:B,"<=2024-02-31",Work_Orders!F:F,"Completed") -> 0 | D22: =SUMIFS(Work_Orders!I:I,Work_Orders!B:B,">=2024-02-01",Work_Orders!B:B,"<=2024-02-31") -> 0
A23: Mar | B23: =COUNTIFS(Work_Orders!B:B,">=2024-03-01",Work_Orders!B:B,"<=2024-03-31") -> 0 | C23: =COUNTIFS(Work_Orders!B:B,">=2024-03-01",Work_Orders!B:B,"<=2024-03-31",Work_Orders!F:F,"Completed") -> 0 | D23: =SUMIFS(Work_Orders!I:I,Work_Orders!B:B,">=2024-03-01",Work_Orders!B:B,"<=2024-03-31") -> 0
A24: Apr | B24: =COUNTIFS(Work_Orders!B:B,">=2024-04-01",Work_Orders!B:B,"<=2024-04-31") -> 0 | C24: =COUNTIFS(Work_Orders!B:B,">=2024-04-01",Work_Orders!B:B,"<=2024-04-31",Work_Orders!F:F,"Completed") -> 0 | D24: =SUMIFS(Work_Orders!I:I,Work_Orders!B:B,">=2024-04-01",Work_Orders!B:B,"<=2024-04-31") -> 0
A25: May | B25: =COUNTIFS(Work_Orders!B:B,">=2024-05-01",Work_Orders!B:B,"<=2024-05-31") -> 0 | C25: =COUNTIFS(Work_Orders!B:B,">=2024-05-01",Work_Orders!B:B,"<=2024-05-31",Work_Orders!F:F,"Completed") -> 0 | D25: =SUMIFS(Work_Orders!I:I,Work_Orders!B:B,">=2024-05-01",Work_Orders!B:B,"<=2024-05-31") -> 0
A26: Jun | B26: =COUNTIFS(Work_Orders!B:B,">=2024-06-01",Work_Orders!B:B,"<=2024-06-31") -> 0 | C26: =COUNTIFS(Work_Orders!B:B,">=2024-06-01",Work_Orders!B:B,"<=2024-06-31",Work_Orders!F:F,"Completed") -> 0 | D26: =SUMIFS(Work_Orders!I:I,Work_Orders!B:B,">=2024-06-01",Work_Orders!B:B,"<=2024-06-31") -> 0
A27: Jul | B27: =COUNTIFS(Work_Orders!B:B,">=2024-07-01",Work_Orders!B:B,"<=2024-07-31") -> 0 | C27: =COUNTIFS(Work_Orders!B:B,">=2024-07-01",Work_Orders!B:B,"<=2024-07-31",Work_Orders!F:F,"Completed") -> 0 | D27: =SUMIFS(Work_Orders!I:I,Work_Orders!B:B,">=2024-07-01",Work_Orders!B:B,"<=2024-07-31") -> 0
A28: Aug | B28: =COUNTIFS(Work_Orders!B:B,">=2024-08-01",Work_Orders!B:B,"<=2024-08-31") -> 0 | C28: =COUNTIFS(Work_Orders!B:B,">=2024-08-01",Work_Orders!B:B,"<=2024-08-31",Work_Orders!F:F,"Completed") -> 0 | D28: =SUMIFS(Work_Orders!I:I,Work_Orders!B:B,">=2024-08-01",Work_Orders!B:B,"<=2024-08-31") -> 0
A29: Sep | B29: =COUNTIFS(Work_Orders!B:B,">=2024-09-01",Work_Orders!B:B,"<=2024-09-31") -> 0 | C29: =COUNTIFS(Work_Orders!B:B,">=2024-09-01",Work_Orders!B:B,"<=2024-09-31",Work_Orders!F:F,"Completed") -> 0 | D29: =SUMIFS(Work_Orders!I:I,Work_Orders!B:B,">=2024-09-01",Work_Orders!B:B,"<=2024-09-31") -> 0
A30: Oct | B30: =COUNTIFS(Work_Orders!B:B,">=2024-10-01",Work_Orders!B:B,"<=2024-10-31") -> 0 | C30: =COUNTIFS(Work_Orders!B:B,">=2024-10-01",Work_Orders!B:B,"<=2024-10-31",Work_Orders!F:F,"Completed") -> 0 | D30: =SUMIFS(Work_Orders!I:I,Work_Orders!B:B,">=2024-10-01",Work_Orders!B:B,"<=2024-10-31") -> 0
A31: Nov | B31: =COUNTIFS(Work_Orders!B:B,">=2024-11-01",Work_Orders!B:B,"<=2024-11-31") -> 0 | C31: =COUNTIFS(Work_Orders!B:B,">=2024-11-01",Work_Orders!B:B,"<=2024-11-31",Work_Orders!F:F,"Completed") -> 0 | D31: =SUMIFS(Work_Orders!I:I,Work_Orders!B:B,">=2024-11-01",Work_Orders!B:B,"<=2024-11-31") -> 0
A32: Dec | B32: =COUNTIFS(Work_Orders!B:B,">=2024-12-01",Work_Orders!B:B,"<=2024-12-31") -> 0 | C32: =COUNTIFS(Work_Orders!B:B,">=2024-12-01",Work_Orders!B:B,"<=2024-12-31",Work_Orders!F:F,"Completed") -> 0 | D32: =SUMIFS(Work_Orders!I:I,Work_Orders!B:B,">=2024-12-01",Work_Orders!B:B,"<=2024-12-31") -> 0

Sheet SQL_Queries
A1: SQL QUERY REFERENCE — Facilities Maintenance Dashboard
A3: Query 1: Total work orders by category
A4: SELECT Category,
A5: COUNT(*) AS Total_Jobs,
A6: ROUND(COUNT(*) * 100.0 / (SELECT COUNT(*) FROM work_orders), 1) AS Pct_Total
A7: FROM work_orders
A8: GROUP BY Category
A9: ORDER BY Total_Jobs DESC;
A11: Query 2: Average days to close by priority
A12: SELECT Priority,
A13: COUNT(*) AS Jobs,
A14: ROUND(AVG(Days_to_Close), 1) AS Avg_Days_to_Close,
... A51: ORDER BY Total_Jobs DESC;

Sheet GitHub_README
A1: GITHUB README TEMPLATE — Copy this into your repository
A3: # Facilities Maintenance Dashboard
A5: ## Project Overview
A6: This project analyses 12 months of fictional facilities maintenance work order data
A7: modelled on a large Irish institutional setting (similar to RCSI). The goal is to
A8: identify maintenance trends, contractor performance, and cost patterns.
A10: ## Tools Used
A11: - Microsoft Excel (data storage, COUNTIFS/AVERAGEIFS formulas, bar & pie charts)
A12: - SQL (data querying and aggregation — see SQL_Queries sheet)
A13: - GitHub (version control and portfolio publishing)
A15: ## Dataset
A16: - 120+ fictional work orders across Jan–Dec 2024
... A36: LinkedIn: [your LinkedIn URL] | Email: punj28@yahoo.com
